<?xml version="1.0" encoding="utf-8"?>
<!-- This URDF was automatically created by SolidWorks to URDF Exporter! Originally created by Stephen Brawner (brawner@gmail.com) 
     Commit Version: 1.6.0-4-g7f85cfe  Build Version: 1.6.7995.38578
     For more information, please see http://wiki.ros.org/sw_urdf_exporter -->
<robot
  name="robotarm1">
  <link
    name="base_link">
    <inertial>
      <origin
        xyz="0.0035407 -1.3568E-06 0.025751"
        rpy="0 0 0" />
      <mass
        value="0.4726" />
      <inertia
        ixx="0.00072672"
        ixy="-5.0643E-10"
        ixz="-1.7068E-05"
        iyy="0.00071621"
        iyz="2.091E-09"
        izz="0.0011346" />
    </inertial>
    <visual>
      <origin
        xyz="0 0 0"
        rpy="0 0 0" />
      <geometry>
        <mesh
          filename="package://robotarm_description/meshes/base_link.STL" />
      </geometry>
      <material
        name="">
        <color
          rgba="0.75294 0.75294 0.75294 1" />
      </material>
    </visual>
    <collision>
      <origin
        xyz="0 0 0"
        rpy="0 0 0" />
      <geometry>
        <mesh
          filename="package://robotarm_description/meshes/base_link.STL" />
      </geometry>
    </collision>
  </link>
  <link
    name="link_1">
    <inertial>
      <origin
        xyz="-4.9898E-05 0.00017226 0.022722"
        rpy="0 0 0" />
      <mass
        value="0.25582" />
      <inertia
        ixx="0.00016823"
        ixy="-3.9638E-10"
        ixz="7.118E-09"
        iyy="0.00018112"
        iyz="1.3521E-07"
        izz="0.00027506" />
    </inertial>
    <visual>
      <origin
        xyz="0 0 0"
        rpy="0 0 0" />
      <geometry>
        <mesh
          filename="package://robotarm_description/meshes/link_1.STL" />
      </geometry>
      <material
        name="">
        <color
          rgba="0.75294 0.75294 0.75294 1" />
      </material>
    </visual>
    <collision>
      <origin
        xyz="0 0 0"
        rpy="0 0 0" />
      <geometry>
        <mesh
          filename="package://robotarm_description/meshes/link_1.STL" />
      </geometry>
    </collision>
  </link>
  <joint
    name="joint_1"
    type="revolute">
    <origin
      xyz="0 0 0.0617"
      rpy="0 0 0" />
    <parent
      link="base_link" />
    <child
      link="link_1" />
    <axis
      xyz="0 0 -1" />
    <limit
      lower="-1.571"
      upper="1.571"
      effort="8.33"
      velocity="1" />
  </joint>
  <link
    name="link_2">
    <inertial>
      <origin
        xyz="-0.14839 -0.035723 -0.00051627"
        rpy="0 0 0" />
      <mass
        value="0.2619" />
      <inertia
        ixx="0.00011734"
        ixy="9.7901E-08"
        ixz="-2.6563E-07"
        iyy="0.00020884"
        iyz="-8.1261E-10"
        izz="0.00024931" />
    </inertial>
    <visual>
      <origin
        xyz="0 0 0"
        rpy="0 0 0" />
      <geometry>
        <mesh
          filename="package://robotarm_description/meshes/link_2.STL" />
      </geometry>
      <material
        name="">
        <color
          rgba="0.75294 0.75294 0.75294 1" />
      </material>
    </visual>
    <collision>
      <origin
        xyz="0 0 0"
        rpy="0 0 0" />
      <geometry>
        <mesh
          filename="package://robotarm_description/meshes/link_2.STL" />
      </geometry>
    </collision>
  </link>
  <joint
    name="joint_2"
    type="revolute">
    <origin
      xyz="-0.0002 0.03525 0.0605"
      rpy="0 0 0" />
    <parent
      link="link_1" />
    <child
      link="link_2" />
    <axis
      xyz="0 1 0" />
    <limit
      lower="0.0"
      upper="3.142"
      effort="15.7"
      velocity="1" />
  </joint>
  <link
    name="link_3">
    <inertial>
      <origin
        xyz="0.13843 -0.036185 0.042336"
        rpy="0 0 0" />
      <mass
        value="0.23372" />
      <inertia
        ixx="0.00012659"
        ixy="7.9944E-08"
        ixz="-2.7322E-05"
        iyy="0.00021713"
        iyz="-1.1736E-09"
        izz="0.00024224" />
    </inertial>
    <visual>
      <origin
        xyz="0 0 0"
        rpy="0 0 0" />
      <geometry>
        <mesh
          filename="package://robotarm_description/meshes/link_3.STL" />
      </geometry>
      <material
        name="">
        <color
          rgba="0.75294 0.75294 0.75294 1" />
      </material>
    </visual>
    <collision>
      <origin
        xyz="0 0 0"
        rpy="0 0 0" />
      <geometry>
        <mesh
          filename="package://robotarm_description/meshes/link_3.STL" />
      </geometry>
    </collision>
  </link>
  <joint
    name="joint_3"
    type="revolute">
    <origin
      xyz="-0.26 -0.00065 -0.00065"
      rpy="0 0 0" />
    <parent
      link="link_2" />
    <child
      link="link_3" />
    <axis
      xyz="0 -1 0" />
    <limit
      lower="0"
      upper="3.142"
      effort="15.7"
      velocity="1" />
  </joint>
  <link
    name="link_4">
    <inertial>
      <origin
        xyz="0.051218 -0.032837 -0.013758"
        rpy="0 0 0" />
      <mass
        value="0.11094" />
      <inertia
        ixx="7.8087E-05"
        ixy="-1.8418E-09"
        ixz="2.4173E-07"
        iyy="6.4212E-05"
        iyz="-1.2842E-09"
        izz="5.1318E-05" />
    </inertial>
    <visual>
      <origin
        xyz="0 0 0"
        rpy="0 0 0" />
      <geometry>
        <mesh
          filename="package://robotarm_description/meshes/link_4.STL" />
      </geometry>
      <material
        name="">
        <color
          rgba="0.75294 0.75294 0.75294 1" />
      </material>
    </visual>
    <collision>
      <origin
        xyz="0 0 0"
        rpy="0 0 0" />
      <geometry>
        <mesh
          filename="package://robotarm_description/meshes/link_4.STL" />
      </geometry>
    </collision>
  </link>
  <joint
    name="joint_4"
    type="revolute">
    <origin
      xyz="0.2602 -0.00325 0.046162"
      rpy="0 0 0" />
    <parent
      link="link_3" />
    <child
      link="link_4" />
    <axis
      xyz="0 1 0" />
    <limit
      lower="-1.571"
      upper="1.571"
      effort="8.34"
      velocity="1" />
  </joint>
  <link
    name="link_5">
    <inertial>
      <origin
        xyz="0.038487 -0.0023009 -0.0005271"
        rpy="0 0 0" />
      <mass
        value="0.15528" />
      <inertia
        ixx="0.00015548"
        ixy="-1.4207E-06"
        ixz="-1.9441E-06"
        iyy="8.0351E-05"
        iyz="1.1046E-07"
        izz="0.00014779" />
    </inertial>
    <visual>
      <origin
        xyz="0 0 0"
        rpy="0 0 0" />
      <geometry>
        <mesh
          filename="package://robotarm_description/meshes/link_5.STL" />
      </geometry>
      <material
        name="">
        <color
          rgba="0.79216 0.81961 0.93333 1" />
      </material>
    </visual>
    <collision>
      <origin
        xyz="0 0 0"
        rpy="0 0 0" />
      <geometry>
        <mesh
          filename="package://robotarm_description/meshes/link_5.STL" />
      </geometry>
    </collision>
  </link>
  <joint
    name="joint_5"
    type="revolute">
    <origin
      xyz="0.0947 -0.03305 0.0003"
      rpy="0 0 0" />
    <parent
      link="link_4" />
    <child
      link="link_5" />
    <axis
      xyz="1 0 0" />
    <limit
      lower="-1.571"
      upper="1.571"
      effort="8.34"
      velocity="1" />
  </joint>
  
  
  <!-- Minimal TCP link (zero mass, small collision box) -->
  <link name="tcp_link">
    <inertial>
      <mass value="0.001" />  <!-- Near-zero mass -->
      <inertia ixx="1e-6" ixy="0" ixz="0" iyy="1e-6" iyz="0" izz="1e-6" />
    </inertial>
    <visual>
      <geometry><box size="0.0001 0.0001 0.0001"/></geometry>  <!-- Tiny -->
    </visual>
    <!-- <collision>
      <geometry><box size="0.0001 0.0001 0.0001"/></geometry>
    </collision> -->
  </link>
  
  <!-- TCP Joint -->
  <joint name="tcp_joint" type="revolute">
    <origin xyz="0.12 0 0" rpy="0 0 0" />
    <parent link="link_5" />
    <child link="tcp_link" />  <!-- Child is now tcp_link -->
    <axis xyz="0 0 1" />
    <limit lower="-1.57" upper="1.57" effort="8.33" velocity="1" />
  </joint>
  
  <link
    name="link_6">
    <inertial>
      <origin
        xyz="0.024202 0.0075855 0.02005"
        rpy="0 0 0" />
      <mass
        value="0.011608" />
      <inertia
        ixx="2.0209E-06"
        ixy="4.1461E-07"
        ixz="4.8679E-20"
        iyy="8.1278E-06"
        iyz="-1.6936E-20"
        izz="7.0746E-06" />
    </inertial>
    <visual>
      <origin
        xyz="0 0 0"
        rpy="0 0 0" />
      <geometry>
        <mesh
          filename="package://robotarm_description/meshes/link_6.STL" />
      </geometry>
      <material
        name="">
        <color
          rgba="0.25098 0.25098 0.25098 1" />
      </material>
    </visual>
    <collision>
      <origin
        xyz="0 0 0"
        rpy="0 0 0" />
      <geometry>
        <mesh
          filename="package://robotarm_description/meshes/link_6.STL" />
      </geometry>
    </collision>
  </link>
  <joint
    name="joint_6"
    type="prismatic">
    <origin
      xyz="0.075 0 -0.02"
      rpy="0 0 0" />
    <parent
      link="link_5" />
    <child
      link="link_6" />
    <axis
      xyz="0 1 0" />
    <limit
      lower="0"
      upper="0.04"
      effort="3.34"
      velocity="1" />
    <mimic
      joint="joint_7"
      multiplier="-1"
      offset="0" />
  </joint>
  <link
    name="link_7">
    <inertial>
      <origin
        xyz="0.024202 -0.0074541 0.02005"
        rpy="0 0 0" />
      <mass
        value="0.011608" />
      <inertia
        ixx="2.0209E-06"
        ixy="-4.1461E-07"
        ixz="3.9129E-19"
        iyy="8.1278E-06"
        iyz="5.7177E-21"
        izz="7.0746E-06" />
    </inertial>
    <visual>
      <origin
        xyz="0 0 0"
        rpy="0 0 0" />
      <geometry>
        <mesh
          filename="package://robotarm_description/meshes/link_7.STL" />
      </geometry>
      <material
        name="">
        <color
          rgba="0.25098 0.25098 0.25098 1" />
      </material>
    </visual>
    <collision>
      <origin
        xyz="0 0 0"
        rpy="0 0 0" />
      <geometry>
        <mesh
          filename="package://robotarm_description/meshes/link_7.STL" />
      </geometry>
    </collision>
  </link>
  <joint
    name="joint_7"
    type="prismatic">
    <origin
      xyz="0.075 0 -0.02"
      rpy="0 0 0" />
    <parent
      link="link_5" />
    <child
      link="link_7" />
    <axis
      xyz="0 1 0" />
    <limit
      lower="-0.04"
      upper="0"
      effort="3.34"
      velocity="1" />
  </joint>
</robot>
