<?xml version="1.0" encoding="utf-8"?>
<!-- This URDF was automatically created by SolidWorks to URDF Exporter! Originally created by Stephen Brawner (brawner@gmail.com) 
     Commit Version: 1.6.0-4-g7f85cfe  Build Version: 1.6.7995.38578
     For more information, please see http://wiki.ros.org/sw_urdf_exporter -->
<robot
  name="cocoabot">
  <link
    name="base_link">
    <inertial>
      <origin
        xyz="-0.0059967 -6.7677E-06 0.027014"
        rpy="0 0 0" />
      <mass
        value="0.15177" />
      <inertia
        ixx="7.464E-05"
        ixy="1.8188E-08"
        ixz="-9.3557E-06"
        iyy="8.7507E-05"
        iyz="1.1412E-08"
        izz="9.5885E-05" />
    </inertial>
    <visual>
      <origin
        xyz="0 0 0"
        rpy="0 0 0" />
      <geometry>
        <mesh
          filename="package://robotarm_description/meshes/base_link.STL" />
      </geometry>
      <material
        name="">
        <color
          rgba="0.75294 0.75294 0.75294 1" />
      </material>
    </visual>
    <collision>
      <origin
        xyz="0 0 0"
        rpy="0 0 0" />
      <geometry>
        <mesh
          filename="package://robotarm_description/meshes/base_link.STL" />
      </geometry>
    </collision>
  </link>
  <link
    name="link_1">
    <inertial>
      <origin
        xyz="-8.0894E-06 -6.4633E-07 0.025939"
        rpy="0 0 0" />
      <mass
        value="0.19298" />
      <inertia
        ixx="0.00027177"
        ixy="3.7065E-09"
        ixz="-1.2071E-08"
        iyy="6.3757E-05"
        iyz="3.176E-09"
        izz="0.0002593" />
    </inertial>
    <visual>
      <origin
        xyz="0 0 0"
        rpy="0 0 0" />
      <geometry>
        <mesh
          filename="package://robotarm_description/meshes/link_1.STL" />
      </geometry>
      <material
        name="">
        <color
          rgba="0.75294 0.75294 0.75294 1" />
      </material>
    </visual>
    <collision>
      <origin
        xyz="0 0 0"
        rpy="0 0 0" />
      <geometry>
        <mesh
          filename="package://robotarm_description/meshes/link_1.STL" />
      </geometry>
    </collision>
  </link>
  <joint
    name="joint_1"
    type="revolute">
    <origin
      xyz="0 0 0.0627"
      rpy="0 0 0" />
    <parent
      link="base_link" />
    <child
      link="link_1" />
    <axis
      xyz="0 0 1" />
    <limit
      lower="-1.57"
      upper="1.57"
      effort="8.33"
      velocity="1" />
  </joint>
  <link
    name="link_2">
    <inertial>
      <origin
        xyz="-0.18066 1.2104E-05 -4.5692E-09"
        rpy="0 0 0" />
      <mass
        value="0.34787" />
      <inertia
        ixx="0.00027059"
        ixy="-1.1961E-08"
        ixz="4.3844E-11"
        iyy="0.00046214"
        iyz="3.6699E-09"
        izz="0.00063079" />
    </inertial>
    <visual>
      <origin
        xyz="0 0 0"
        rpy="0 0 0" />
      <geometry>
        <mesh
          filename="package://robotarm_description/meshes/link_2.STL" />
      </geometry>
      <material
        name="">
        <color
          rgba="0.75294 0.75294 0.75294 1" />
      </material>
    </visual>
    <collision>
      <origin
        xyz="0 0 0"
        rpy="0 0 0" />
      <geometry>
        <mesh
          filename="package://robotarm_description/meshes/link_2.STL" />
      </geometry>
    </collision>
  </link>
  <joint
    name="joint_2"
    type="revolute">
    <origin
      xyz="0 0 0.058"
      rpy="0 0 0" />
    <parent
      link="link_1" />
    <child
      link="link_2" />
    <axis
      xyz="0 1 0" />
    <limit
      lower="0"
      upper="3.142"
      effort="16.67"
      velocity="1" />
  </joint>
  <link
    name="link_3">
    <inertial>
      <origin
        xyz="-4.7017E-05 0.041376 -0.13628"
        rpy="0 0 0" />
      <mass
        value="0.24803" />
      <inertia
        ixx="0.00042126"
        ixy="7.0299E-10"
        ixz="-2.4202E-07"
        iyy="0.00039925"
        iyz="5.2768E-07"
        izz="7.1938E-05" />
    </inertial>
    <visual>
      <origin
        xyz="0 0 0"
        rpy="0 0 0" />
      <geometry>
        <mesh
          filename="package://robotarm_description/meshes/link_3.STL" />
      </geometry>
      <material
        name="">
        <color
          rgba="0.75294 0.75294 0.75294 1" />
      </material>
    </visual>
    <collision>
      <origin
        xyz="0 0 0"
        rpy="0 0 0" />
      <geometry>
        <mesh
          filename="package://robotarm_description/meshes/link_3.STL" />
      </geometry>
    </collision>
  </link>
  <joint
    name="joint_3"
    type="revolute">
    <origin
      xyz="-0.291 0 0"
      rpy="1.5708 0 -1.5708" />
    <parent
      link="link_2" />
    <child
      link="link_3" />
    <axis
      xyz="-1 0 0" />
    <limit
      lower="-3.142"
      upper="0"
      effort="16.67"
      velocity="1" />
  </joint>
  <link
    name="link_4">
    <inertial>
      <origin
        xyz="0.052835 1.2217E-05 -0.016519"
        rpy="0 0 0" />
      <mass
        value="0.13001" />
      <inertia
        ixx="7.9678E-05"
        ixy="-1.8435E-09"
        ixz="2.4138E-07"
        iyy="6.6322E-05"
        iyz="-1.2533E-09"
        izz="5.306E-05" />
    </inertial>
    <visual>
      <origin
        xyz="0 0 0"
        rpy="0 0 0" />
      <geometry>
        <mesh
          filename="package://robotarm_description/meshes/link_4.STL" />
      </geometry>
      <material
        name="">
        <color
          rgba="0.75294 0.75294 0.75294 1" />
      </material>
    </visual>
    <collision>
      <origin
        xyz="0 0 0"
        rpy="0 0 0" />
      <geometry>
        <mesh
          filename="package://robotarm_description/meshes/link_4.STL" />
      </geometry>
    </collision>
  </link>
  <joint
    name="joint_4"
    type="revolute">
    <origin
      xyz="5E-05 0.043049 -0.29"
      rpy="-1.5708 1.5708 0" />
    <parent
      link="link_3" />
    <child
      link="link_4" />
    <axis
      xyz="0 -1 0" />
    <limit
      lower="-1.57"
      upper="1.57"
      effort="8.33"
      velocity="1" />
  </joint>
  <link
    name="link_5">
    <inertial>
      <origin
        xyz="0.026738 -0.0022941 -0.011858"
        rpy="0 0 0" />
      <mass
        value="0.35342" />
      <inertia
        ixx="0.00044308"
        ixy="-5.6767E-06"
        ixz="1.0397E-05"
        iyy="0.00026219"
        iyz="-2.9173E-07"
        izz="0.00036417" />
    </inertial>
    <visual>
      <origin
        xyz="0 0 0"
        rpy="0 0 0" />
      <geometry>
        <mesh
          filename="package://robotarm_description/meshes/link_5.STL" />
      </geometry>
      <material
        name="">
        <color
          rgba="1 0.85882 0.07451 1" />
      </material>
    </visual>
    <collision>
      <origin
        xyz="0 0 0"
        rpy="0 0 0" />
      <geometry>
        <mesh
          filename="package://robotarm_description/meshes/link_5.STL" />
      </geometry>
    </collision>
  </link>
  <joint
    name="joint_5"
    type="revolute">
    <origin
      xyz="0.0947 -1.9981E-05 -5.0149E-05"
      rpy="0 0 0" />
    <parent
      link="link_4" />
    <child
      link="link_5" />
    <axis
      xyz="1 0 0" />
    <limit
      lower="-1.57"
      upper="1.57"
      effort="8.33"
      velocity="1" />
  </joint>

  <!-- Minimal TCP link (zero mass, small collision box) -->
  <link name="tcp_link">
    <inertial>
      <mass value="0.001" />  <!-- Near-zero mass -->
      <inertia ixx="1e-6" ixy="0" ixz="0" iyy="1e-6" iyz="0" izz="1e-6" />
    </inertial>
    <visual>
      <geometry><box size="0.0001 0.0001 0.0001"/></geometry>  <!-- Tiny -->
    </visual>
    <!-- <collision>
      <geometry><box size="0.0001 0.0001 0.0001"/></geometry>
    </collision> -->
  </link>

  <!-- TCP Joint -->
  <joint name="tcp_joint" type="revolute">
    <origin xyz="0.125 0 -0.03" rpy="0 0 0" />
    <parent link="link_5" />
    <child link="tcp_link" />  <!-- Child is now tcp_link -->
    <axis xyz="0 0 1" />
    <limit lower="-1.57" upper="1.57" effort="8.33" velocity="1" />
  </joint>

  <link
    name="camera_link">
    <inertial>
      <origin
        xyz="-0.0085656 -3.6947E-05 -0.00041323"
        rpy="0 0 0" />
      <mass
        value="0.036716" />
      <inertia
        ixx="2.0023E-05"
        ixy="1.0941E-08"
        ixz="-1.0141E-07"
        iyy="4E-06"
        iyz="5.6099E-10"
        izz="1.7466E-05" />
    </inertial>
    <visual>
      <origin
        xyz="0 0 0"
        rpy="0 0 0" />
      <geometry>
        <mesh
          filename="package://robotarm_description/meshes/camera_link.STL" />
      </geometry>
      <material
        name="">
        <color
          rgba="0.50196 0.50196 0.50196 1" />
      </material>
    </visual>
    <collision>
      <origin
        xyz="0 0 0"
        rpy="0 0 0" />
      <geometry>
        <mesh
          filename="package://robotarm_description/meshes/camera_link.STL" />
      </geometry>
    </collision>
  </link>
  <joint
    name="camera_joint"
    type="fixed">
    <origin
      xyz="0.02 1.9981E-05 0.10926"
      rpy="0 0 0" />
    <parent
      link="link_5" />
    <child
      link="camera_link" />
    <axis
      xyz="0 0 0" />
  </joint>
  <link
    name="left_cutter_link">
    <inertial>
      <origin
        xyz="-0.021488 0.008521 0.0014556"
        rpy="0 0 0" />
      <mass
        value="0.0091779" />
      <inertia
        ixx="4.3618E-07"
        ixy="4.87E-07"
        ixz="1.5736E-10"
        iyy="2.6984E-06"
        iyz="-9.1428E-12"
        izz="3.0669E-06" />
    </inertial>
    <visual>
      <origin
        xyz="0 0 0"
        rpy="0 0 0" />
      <geometry>
        <mesh
          filename="package://robotarm_description/meshes/left_cutter_link.STL" />
      </geometry>
      <material
        name="">
        <color
          rgba="0.50196 0.50196 0.50196 1" />
      </material>
    </visual>
    <collision>
      <origin
        xyz="0 0 0"
        rpy="0 0 0" />
      <geometry>
        <mesh
          filename="package://robotarm_description/meshes/left_cutter_link.STL" />
      </geometry>
    </collision>
  </link>
  <joint
    name="left_cutter_joint"
    type="revolute">
    <origin
      xyz="0.108 0.00051998 0.061225"
      rpy="0 0 0" />
    <parent
      link="link_5" />
    <child
      link="left_cutter_link" />
    <axis
      xyz="0 0 1" />
    <limit
      lower="-0.7"
      upper="0"
      effort="8.33"
      velocity="1" />
    <mimic
      joint="right_cutter_joint"
      multiplier="-1"
      offset="0" />
  </joint>
  <link
    name="right_cutter_link">
    <inertial>
      <origin
        xyz="-0.019619 -0.012992 0.0044867"
        rpy="0 0 0" />
      <mass
        value="0.0092969" />
      <inertia
        ixx="5.3406E-07"
        ixy="-8.173E-07"
        ixz="-9.0022E-12"
        iyy="3.6643E-06"
        iyz="8.639E-11"
        izz="4.1286E-06" />
    </inertial>
    <visual>
      <origin
        xyz="0 0 0"
        rpy="0 0 0" />
      <geometry>
        <mesh
          filename="package://robotarm_description/meshes/right_cutter_link.STL" />
      </geometry>
      <material
        name="">
        <color
          rgba="0.50196 0.50196 0.50196 1" />
      </material>
    </visual>
    <collision>
      <origin
        xyz="0 0 0"
        rpy="0 0 0" />
      <geometry>
        <mesh
          filename="package://robotarm_description/meshes/right_cutter_link.STL" />
      </geometry>
    </collision>
  </link>
  <joint
    name="right_cutter_joint"
    type="revolute">
    <origin
      xyz="0.108 0.00051998 0.061225"
      rpy="0 0 0" />
    <parent
      link="link_5" />
    <child
      link="right_cutter_link" />
    <axis
      xyz="0 0 1" />
    <limit
      lower="0"
      upper="0.7"
      effort="8.33"
      velocity="1" />
  </joint>
  <link
    name="left_gripper_link">
    <inertial>
      <origin
        xyz="0.038215 -0.0038528 0.014998"
        rpy="0 0 0" />
      <mass
        value="0.06688" />
      <inertia
        ixx="9.8102E-06"
        ixy="4.667E-06"
        ixz="-4.5258E-09"
        iyy="5.8123E-05"
        iyz="4.9868E-10"
        izz="5.8183E-05" />
    </inertial>
    <visual>
      <origin
        xyz="0 0 0"
        rpy="0 0 0" />
      <geometry>
        <mesh
          filename="package://robotarm_description/meshes/left_gripper_link.STL" />
      </geometry>
      <material
        name="">
        <color
          rgba="1 0.85882 0.07451 1" />
      </material>
    </visual>
    <collision>
      <origin
        xyz="0 0 0"
        rpy="0 0 0" />
      <geometry>
        <mesh
          filename="package://robotarm_description/meshes/left_gripper_link.STL" />
      </geometry>
    </collision>
  </link>
  <joint
    name="left_gripper_joint"
    type="revolute">
    <origin
      xyz="0.033 0.020514 -0.04675"
      rpy="0 0 0" />
    <parent
      link="link_5" />
    <child
      link="left_gripper_link" />
    <axis
      xyz="0 0 1" />
    <limit
      lower="0"
      upper="0.7"
      effort="8.33"
      velocity="1" />
    <mimic
      joint="right_gripper_joint"
      multiplier="1"
      offset="0" />
  </joint>
  <link
    name="right_gripper_link">
    <inertial>
      <origin
        xyz="0.043039 0.0051582 0.014914"
        rpy="0 0 0" />
      <mass
        value="0.059471" />
      <inertia
        ixx="9.1148E-06"
        ixy="-5.57E-06"
        ixz="-8.8026E-09"
        iyy="5.7007E-05"
        iyz="-8.9018E-10"
        izz="5.7422E-05" />
    </inertial>
    <visual>
      <origin
        xyz="0 0 0"
        rpy="0 0 0" />
      <geometry>
        <mesh
          filename="package://robotarm_description/meshes/right_gripper_link.STL" />
      </geometry>
      <material
        name="">
        <color
          rgba="1 0.85882 0.07451 1" />
      </material>
    </visual>
    <collision>
      <origin
        xyz="0 0 0"
        rpy="0 0 0" />
      <geometry>
        <mesh
          filename="package://robotarm_description/meshes/right_gripper_link.STL" />
      </geometry>
    </collision>
  </link>
  <joint
    name="right_gripper_joint"
    type="revolute">
    <origin
      xyz="0.033701 -0.01948 -0.04675"
      rpy="0 0 0" />
    <parent
      link="link_5" />
    <child
      link="right_gripper_link" />
    <axis
      xyz="0 0 -1" />
    <limit
      lower="0"
      upper="0.7"
      effort="8.33"
      velocity="1" />
  </joint>
</robot>