<?xml version="1.0" encoding="utf-8"?>
<!-- This URDF was automatically created by SolidWorks to URDF Exporter! Originally created by Stephen Brawner (brawner@gmail.com) 
     Commit Version: 1.6.0-4-g7f85cfe  Build Version: 1.6.7995.38578
     For more information, please see http://wiki.ros.org/sw_urdf_exporter -->
<robot
  name="robotarm">
  <link
    name="base_link">
    <inertial>
      <origin
        xyz="-0.0021617 3.2167E-06 0.025888"
        rpy="0 0 0" />
      <mass
        value="0.49164" />
      <inertia
        ixx="0.00072844"
        ixy="-5.3735E-10"
        ixz="1.7051E-05"
        iyy="0.00071827"
        iyz="-2.0927E-09"
        izz="0.0011362" />
    </inertial>
    <visual>
      <origin
        xyz="0 0 0"
        rpy="0 0 0" />
      <geometry>
        <mesh
          filename="package://robotarm_description/meshes/base_link.STL" />
      </geometry>
      <material
        name="">
        <color
          rgba="0.75294 0.75294 0.75294 1" />
      </material>
    </visual>
    <collision>
      <origin
        xyz="0 0 0"
        rpy="0 0 0" />
      <geometry>
        <mesh
          filename="package://robotarm_description/meshes/base_link.STL" />
      </geometry>
    </collision>
  </link>
  <link
    name="link_1">
    <inertial>
      <origin
        xyz="4.934E-05 -0.00025879 0.022977"
        rpy="0 0 0" />
      <mass
        value="0.25792" />
      <inertia
        ixx="0.00016866"
        ixy="-1.8499E-10"
        ixz="-7.6131E-09"
        iyy="0.00018148"
        iyz="1.65E-07"
        izz="0.00027543" />
    </inertial>
    <visual>
      <origin
        xyz="0 0 0"
        rpy="0 0 0" />
      <geometry>
        <mesh
          filename="package://robotarm_description/meshes/link_1.STL" />
      </geometry>
      <material
        name="">
        <color
          rgba="0.75294 0.75294 0.75294 1" />
      </material>
    </visual>
    <collision>
      <origin
        xyz="0 0 0"
        rpy="0 0 0" />
      <geometry>
        <mesh
          filename="package://robotarm_description/meshes/link_1.STL" />
      </geometry>
    </collision>
  </link>
  <joint
    name="joint_1"
    type="revolute">
    <origin
      xyz="0 0 0.0632"
      rpy="0 0 0" />
    <parent
      link="base_link" />
    <child
      link="link_1" />
    <axis
      xyz="0 0 -1" />
    <limit
      lower="-1.571"
      upper="1.571"
      effort="8.33"
      velocity="1" />
  </joint>
  <link
    name="link_2">
    <inertial>
      <origin
        xyz="-0.14821 -0.035621 -0.00028824"
        rpy="0 0 0" />
      <mass
        value="0.26072" />
      <inertia
        ixx="0.00011686"
        ixy="7.5116E-08"
        ixz="-2.4827E-07"
        iyy="0.00020757"
        iyz="-1.5576E-09"
        izz="0.00024756" />
    </inertial>
    <visual>
      <origin
        xyz="0 0 0"
        rpy="0 0 0" />
      <geometry>
        <mesh
          filename="package://robotarm_description/meshes/link_2.STL" />
      </geometry>
      <material
        name="">
        <color
          rgba="0.75294 0.75294 0.75294 1" />
      </material>
    </visual>
    <collision>
      <origin
        xyz="0 0 0"
        rpy="0 0 0" />
      <geometry>
        <mesh
          filename="package://robotarm_description/meshes/link_2.STL" />
      </geometry>
    </collision>
  </link>
  <joint
    name="joint_2"
    type="revolute">
    <origin
      xyz="0.0002 0.03575 0.062"
      rpy="0 0 0" />
    <parent
      link="link_1" />
    <child
      link="link_2" />
    <axis
      xyz="0 1 0" />
    <limit
      lower="0"
      upper="3.142"
      effort="15.7"
      velocity="1" />
  </joint>
  <link
    name="link_3">
    <inertial>
      <origin
        xyz="0.14678 -0.035556 0.042761"
        rpy="0 0 0" />
      <mass
        value="0.24699" />
      <inertia
        ixx="0.00012565"
        ixy="3.4941E-08"
        ixz="-2.5179E-05"
        iyy="0.00020183"
        iyz="-3.9334E-09"
        izz="0.00022595" />
    </inertial>
    <visual>
      <origin
        xyz="0 0 0"
        rpy="0 0 0" />
      <geometry>
        <mesh
          filename="package://robotarm_description/meshes/link_3.STL" />
      </geometry>
      <material
        name="">
        <color
          rgba="0.75294 0.75294 0.75294 1" />
      </material>
    </visual>
    <collision>
      <origin
        xyz="0 0 0"
        rpy="0 0 0" />
      <geometry>
        <mesh
          filename="package://robotarm_description/meshes/link_3.STL" />
      </geometry>
    </collision>
  </link>
  <joint
    name="joint_3"
    type="revolute">
    <origin
      xyz="-0.26 5E-05 -0.00025"
      rpy="0 0 0" />
    <parent
      link="link_2" />
    <child
      link="link_3" />
    <axis
      xyz="0 -1 0" />
    <limit
      lower="0"
      upper="3.142"
      effort="15.7"
      velocity="1" />
  </joint>
  <link
    name="link_4">
    <inertial>
      <origin
        xyz="0.052835 -0.032615 -0.016642"
        rpy="0 0 0" />
      <mass
        value="0.13001" />
      <inertia
        ixx="7.9678E-05"
        ixy="-1.8435E-09"
        ixz="2.4138E-07"
        iyy="6.6322E-05"
        iyz="-1.2533E-09"
        izz="5.306E-05" />
    </inertial>
    <visual>
      <origin
        xyz="0 0 0"
        rpy="0 0 0" />
      <geometry>
        <mesh
          filename="package://robotarm_description/meshes/link_4.STL" />
      </geometry>
      <material
        name="">
        <color
          rgba="0.75294 0.75294 0.75294 1" />
      </material>
    </visual>
    <collision>
      <origin
        xyz="0 0 0"
        rpy="0 0 0" />
      <geometry>
        <mesh
          filename="package://robotarm_description/meshes/link_4.STL" />
      </geometry>
    </collision>
  </link>
  <joint
    name="joint_4"
    type="revolute">
    <origin
      xyz="0.2602 -0.00245 0.046362"
      rpy="0 0 0" />
    <parent
      link="link_3" />
    <child
      link="link_4" />
    <axis
      xyz="0 1 0" />
    <limit
      lower="-1.571"
      upper="1.571"
      effort="8.34"
      velocity="1" />
  </joint>
  <link
    name="link_5">
    <inertial>
      <origin
        xyz="0.041261 0.0018859 5.2776E-06"
        rpy="0 0 0" />
      <mass
        value="0.14243" />
      <inertia
        ixx="0.00011598"
        ixy="2.5311E-07"
        ixz="6.9458E-10"
        iyy="5.3508E-05"
        iyz="-3.2934E-09"
        izz="0.00010923" />
    </inertial>
    <visual>
      <origin
        xyz="0 0 0"
        rpy="0 0 0" />
      <geometry>
        <mesh
          filename="package://robotarm_description/meshes/link_5.STL" />
      </geometry>
      <material
        name="">
        <color
          rgba="0.89412 0.89412 0.89412 1" />
      </material>
    </visual>
    <collision>
      <origin
        xyz="0 0 0"
        rpy="0 0 0" />
      <geometry>
        <mesh
          filename="package://robotarm_description/meshes/link_5.STL" />
      </geometry>
    </collision>
  </link>
  <joint
    name="joint_5"
    type="revolute">
    <origin
      xyz="0.0947 -0.03245 -0.0003"
      rpy="0 0 0" />
    <parent
      link="link_4" />
    <child
      link="link_5" />
    <axis
      xyz="1 0 0" />
    <limit
      lower="-1.571"
      upper="1.571"
      effort="8.34"
      velocity="1" />
  </joint>

  <!-- Minimal TCP link (zero mass, small collision box) -->
  <link name="tcp_link">
    <inertial>
      <mass value="0.001" />  <!-- Near-zero mass -->
      <inertia ixx="1e-6" ixy="0" ixz="0" iyy="1e-6" iyz="0" izz="1e-6" />
    </inertial>
    <visual>
      <geometry><box size="0.0001 0.0001 0.0001"/></geometry>  <!-- Tiny -->
    </visual>
    <!-- <collision>
      <geometry><box size="0.0001 0.0001 0.0001"/></geometry>
    </collision> -->
  </link>
  
  <!-- TCP Joint -->
  <joint name="tcp_joint" type="revolute">
    <origin xyz="0.12 0 0" rpy="0 0 0" />
    <parent link="link_5" />
    <child link="tcp_link" />  <!-- Child is now tcp_link -->
    <axis xyz="0 0 1" />
    <limit lower="-1.57" upper="1.57" effort="8.33" velocity="1" />
  </joint>

  <link
    name="link_6">
    <inertial>
      <origin
        xyz="0.02487 0.008464 0.02"
        rpy="0 0 0" />
      <mass
        value="0.012327" />
      <inertia
        ixx="2.0823E-06"
        ixy="7.4626E-07"
        ixz="5.5609E-12"
        iyy="8.611E-06"
        iyz="-6.6849E-13"
        izz="7.4736E-06" />
    </inertial>
    <visual>
      <origin
        xyz="0 0 0"
        rpy="0 0 0" />
      <geometry>
        <mesh
          filename="package://robotarm_description/meshes/link_6.STL" />
      </geometry>
      <material
        name="">
        <color
          rgba="0.25098 0.25098 0.25098 1" />
      </material>
    </visual>
    <collision>
      <origin
        xyz="0 0 0"
        rpy="0 0 0" />
      <geometry>
        <mesh
          filename="package://robotarm_description/meshes/link_6.STL" />
      </geometry>
    </collision>
  </link>
  <joint
    name="joint_6"
    type="prismatic">
    <origin
      xyz="0.072 0 -0.02"
      rpy="0 0 0" />
    <parent
      link="link_5" />
    <child
      link="link_6" />
    <axis
      xyz="0 1 0" />
    <limit
      lower="0"
      upper="0.04"
      effort="3.34"
      velocity="1" />
    <mimic
      joint="joint_7"
      multiplier="-1"
      offset="0" />
  </joint>
  <link
    name="link_7">
    <inertial>
      <origin
        xyz="0.02487 -0.008584 0.02"
        rpy="0 0 0" />
      <mass
        value="0.012327" />
      <inertia
        ixx="2.0823E-06"
        ixy="-7.4626E-07"
        ixz="-5.5609E-12"
        iyy="8.611E-06"
        iyz="-6.6849E-13"
        izz="7.4736E-06" />
    </inertial>
    <visual>
      <origin
        xyz="0 0 0"
        rpy="0 0 0" />
      <geometry>
        <mesh
          filename="package://robotarm_description/meshes/link_7.STL" />
      </geometry>
      <material
        name="">
        <color
          rgba="0.25098 0.25098 0.25098 1" />
      </material>
    </visual>
    <collision>
      <origin
        xyz="0 0 0"
        rpy="0 0 0" />
      <geometry>
        <mesh
          filename="package://robotarm_description/meshes/link_7.STL" />
      </geometry>
    </collision>
  </link>
  <joint
    name="joint_7"
    type="prismatic">
    <origin
      xyz="0.072 0 -0.02"
      rpy="0 0 0" />
    <parent
      link="link_5" />
    <child
      link="link_7" />
    <axis
      xyz="0 1 0" />
    <limit
      lower="-0.04"
      upper="0"
      effort="3.34"
      velocity="1" />
  </joint>
</robot>